## 异常体系

Java异常体系分为`Error`和`Exception`，两者均继承自`Throwable`。

### Error

1. 表示严重的错误，程序直接无力回天。
2. 无需捕获。
3. 如：`OutOfMemoryError`。

> 按照惯例，`Error`留给JVM使用。

### Exception

如果异常不可恢复，则使用`Runtime Exception`，否则使用`Checked Exception`。

> 有时，“是否可恢复”不是那么容易判断的，所以如果不确定异常“是否可恢复”，可将其定义为`Checked Exception`。

#### Runtime Exception

1. 运行时异常。
2. 可以捕获。
3. 如：`NullPointerException`。

#### Checked Exception

1. 检查型异常。
2. 必须捕获，否则编译器会报错。
3. 如：`IOException`。



## Try、Catch、Finally

在多异常捕获中，<u>子异常</u>需放在<u>父异常</u>前。

异常的处理应坚持早暴露、早修复的原则。

### 顺序

如果`catch`中继续抛出异常，也不影响`finally`中代码的执行，JVM会先执行`finally`中的代码，然后再抛出异常。

<span style=background:#fdc200>注意</span>：`finally`中的代码块会在`try`代码块中的`return`语句后、方法的`return`语句之前执行，如示例代码：

```java
public int test(){
    int i = 1;
    try{
        i += 9;
        return i;	 // 代码会在这儿，将i的值返回（放入方法返回值），即，返回“10”。
    }catch(Exception e){
        e.printStackTrace();
        return i;	 // 该return执行完后，还会执行finally中的代码。
    }finally{
        i = 2; 		// finally中的代码还是会执行，即i的值会变为2，但是i的值不会再放入返回区。
        			// 对基本类型来说，return返回的是值，finally对基本类型变量的修改不会影响返回值；
       				// 但对对象来说，return返回的是引用，故finally对对象变量的属性的修改会生效。
    }
    return i;
}
```

但如果`finally`代码块中有`return`语句，该`return`会覆盖`try`代码块中的`return`语句，同时会使方法的`return`语句不可达，即，失效。



## Throw

归根结底，异常都是通过`throw`语句抛出的。

新建异常，或者说异常转型时，需向构造方法中传入**原**异常，不然会丢失原有的**异常栈**。

一般不在`finally`中抛出异常，如果非要，需调用`Throwable.getSuppressed()`。



## Assert

断言执行失败时，会抛出`AssertionError`，故只能用于开发、测试阶段中的不可恢复的程序错误。

JVM默认关闭断言功能，需在启动JVM时传入参数开启。

很少有人用断言，都是用**JUnit**单元测试。

