Java异常体系分为：

1. Error，表示严重的错误，无需捕获。

2. Exception，异常分为：

   1. **Runtime Exception**，可以捕获。
   2. **Checked Exception**，必须捕获，否则编译器会报错。



### Try、Catch、Finally

在多异常捕获中，子异常需放在父异常前。

异常的处理应坚持早暴露、早修复的原则。

如果**catch**中继续抛出异常，也不影响**finally**中代码的执行，JVM会先执行**finally**中的代码，然后再抛出异常。

**finally**中的代码块会在**try**代码块中的**return**语句后、方法的**return**语句之前执行，如示例代码：

```java
public int test(){
    int i = 1;
    try{
        i += 9;
        return i; // 代码会在这儿，将i的值返回（放入方法返回值），即返回“10”。
    }catch(Exception e){
        e.printStackTrace();
        return i; // 该return执行完后，还会执行finally中的代码。
    }finally{
        i = 2; // finally中的代码还是会执行，即i的值会变为2，但是i的值不会再放入返回区。
        // 对基本类型来说，return返回的是值，finally对基本类型变量的修改不会影响返回值；
        // 但对对象来说，return返回的是引用，故finally对对象变量的属性的修改会生效。
    }
    return i;
}
```

但如果**finally**代码块中有**return**语句，该**return**会覆盖**try**代码块中的**return**语句，同时会使方法的**return**语句不可达，即失效。



### Throw

归根结底，异常都是通过**throw**语句抛出的。

新建异常，或者说异常转型时，需向构造方法中传入**原**异常，不然会丢失原有的**异常栈**。

一般不在**finally**中抛出异常，如果非要，需调用<span style=background:#b3b3b3>Throwable.getSuppressed()</span>。



### Assert

断言执行失败时，会抛出AssertionError，故只能用于开发、测试阶段中的不可恢复的程序错误。

JVM默认关闭断言功能，需在启动JVM时传入参数开启。

很少有人用断言，都是用JUnit单元测试。